<?xml version='1.0' encoding='utf-8'?>
<robot xmlns:xacro="http://www.ros.org/wiki/xacro" name="tiago_dual">


<xacro:include filename="$(find tiago_dual_description)/robots/tiago_dual.urdf.xacro"/>

<link name="world"/>
  <joint name="reference" type="floating">
    <parent link="world"/>
    <child link="base_footprint"/>
</joint>

<link name="camera_right_frame"/>
<joint name="camera_right_frame_joint" type="fixed">
    <origin rpy="1.57079632679 0 0" xyz="0.072 -0.085 0.0"/>
    <parent link="wrist_right_ft_tool_link"/>
    <child link="camera_right_frame"/>
</joint>



</robot>
